Workbook

Sheet Bets
A1: Dave Portnoy — Publicly Reported Betting History
A2: Compiled from public reports (X posts, DraftKings-confirmed wagers, media coverage). Blank Wager/Payout cells = amount not publicly reported. Payout & Net are formulas.
A4: Date | B4: Sport | C4: Pick (Team / Side) | D4: Opponent | E4: Bet Type / Details | F4: Sportsbook | G4: Odds (American) | H4: Wager ($) | I4: Result | J4: Total Payout ($) | K4: Net Profit/Loss ($) | L4: Source
A5: 2021-11-20 | B5: CFB | C5: Virginia Tech | D5: Miami | E5: Moneyline | F5: Reported | G5: 220 | H5: 500000 | I5: Loss | J5: =IF(I5="Loss",0,IF(OR(H5="",G5=""),"",IF(G5>0,H5*(1+G5/100),H5*(1+100/ABS(G5))))) -> 0 | K5: =IF(H5="","",IF(I5="Loss",-H5,IF(J5="","",J5-H5))) -> -500000 | L5: OnlineBookiesOffers
A6: 2023-11 | B6: NFL | C6: Multiple NFL bets | D6: Multiple | E6: Aggregate (Nov 2023) | F6: Reported | H6: 120000 | I6: Loss | J6: =IF(I6="Loss",0,IF(OR(H6="",G6=""),"",IF(G6>0,H6*(1+G6/100),H6*(1+100/ABS(G6))))) -> 0 | K6: =IF(H6="","",IF(I6="Loss",-H6,IF(J6="","",J6-H6))) -> -120000 | L6: OnlineBookiesOffers
A7: 2024-01-01 | B7: CFB | C7: Michigan | D7: Alabama | E7: Moneyline — Rose Bowl / CFP Semi | F7: DraftKings | G7: -118 | H7: 1000000 | I7: Win | J7: =IF(I7="Loss",0,IF(OR(H7="",G7=""),"",IF(G7>0,H7*(1+G7/100),H7*(1+100/ABS(G7))))) -> 1847457.6 | K7: =IF(H7="","",IF(I7="Loss",-H7,IF(J7="","",J7-H7))) -> 847457.63 | L7: BetMassachusetts tracker
A8: 2024-02-11 | B8: NFL | C8: Kansas City Chiefs | D8: San Francisco 49ers | E8: Moneyline — Super Bowl LVIII | F8: Reported | H8: 500000 | I8: Win | J8: 1000000 | K8: =IF(H8="","",IF(I8="Loss",-H8,IF(J8="","",J8-H8))) -> 500000 | L8: OnlineBookiesOffers / Fox Business
A9: 2024-02-11 | B9: NFL | C9: Coin toss side | D9: Coin toss | E9: Prop — Super Bowl LVIII coin toss | F9: Reported | G9: -105 | H9: 10000 | I9: Loss | J9: =IF(I9="Loss",0,IF(OR(H9="",G9=""),"",IF(G9>0,H9*(1+G9/100),H9*(1+100/ABS(G9))))) -> 0 | K9: =IF(H9="","",IF(I9="Loss",-H9,IF(J9="","",J9-H9))) -> -10000 | L9: OnlineBookiesOffers
A10: 2024-03-20 | B10: NCAAB | C10: UConn | D10: Field | E10: Futures — NCAA Tournament champion | F10: DraftKings | G10: 360 | H10: 600000 | I10: Win | J10: =IF(I10="Loss",0,IF(OR(H10="",G10=""),"",IF(G10>0,H10*(1+G10/100),H10*(1+100/ABS(G10))))) -> 2760000 | K10: =IF(H10="","",IF(I10="Loss",-H10,IF(J10="","",J10-H10))) -> 2160000 | L10: NBC News / DraftKings confirmed
A11: 2024-04-10 | B11: Golf | C11: Scottie Scheffler | D11: Field | E11: Futures — Masters winner | F11: DraftKings | G11: 450 | H11: 300000 | I11: Win | J11: =IF(I11="Loss",0,IF(OR(H11="",G11=""),"",IF(G11>0,H11*(1+G11/100),H11*(1+100/ABS(G11))))) -> 1650000 | K11: =IF(H11="","",IF(I11="Loss",-H11,IF(J11="","",J11-H11))) -> 1350000 | L11: BetMassachusetts tracker
A12: 2024-04-19 | B12: NHL | C12: Edmonton Oilers | D12: Field | E12: Futures — Stanley Cup champion | F12: DraftKings | G12: 700 | H12: 150000 | I12: Loss | J12: =IF(I12="Loss",0,IF(OR(H12="",G12=""),"",IF(G12>0,H12*(1+G12/100),H12*(1+100/ABS(G12))))) -> 0 | K12: =IF(H12="","",IF(I12="Loss",-H12,IF(J12="","",J12-H12))) -> -150000 | L12: BetMassachusetts tracker
A13: 2024-06-25 | B13: MLB | C13: Philadelphia Phillies | D13: Field | E13: Futures — World Series champion | F13: DraftKings | G13: 600 | H13: 200000 | I13: Loss | J13: =IF(I13="Loss",0,IF(OR(H13="",G13=""),"",IF(G13>0,H13*(1+G13/100),H13*(1+100/ABS(G13))))) -> 0 | K13: =IF(H13="","",IF(I13="Loss",-H13,IF(J13="","",J13-H13))) -> -200000 | L13: BetMassachusetts tracker
A14: 2024-08-11 | B14: WNBA | C14: Indiana Fever | D14: Field | E14: Futures — WNBA champion | F14: DraftKings | G14: 10000 | H14: 100000 | I14: Loss | J14: =IF(I14="Loss",0,IF(OR(H14="",G14=""),"",IF(G14>0,H14*(1+G14/100),H14*(1+100/ABS(G14))))) -> 0 | K14: =IF(H14="","",IF(I14="Loss",-H14,IF(J14="","",J14-H14))) -> -100000 | L14: BetMassachusetts tracker
A15: 2024-09-05 | B15: NFL | C15: Baltimore Ravens | D15: Kansas City Chiefs | E15: Moneyline — season opener | F15: DraftKings | G15: 130 | H15: 300000 | I15: Loss | J15: =IF(I15="Loss",0,IF(OR(H15="",G15=""),"",IF(G15>0,H15*(1+G15/100),H15*(1+100/ABS(G15))))) -> 0 | K15: =IF(H15="","",IF(I15="Loss",-H15,IF(J15="","",J15-H15))) -> -300000 | L15: Las Vegas Review-Journal
A16: 2024-09-06 | B16: WNBA/CFB | C16: Indiana Fever + Michigan | D16: Minnesota Lynx + Texas | E16: 2-leg parlay (both ML) | F16: DraftKings | G16: 650 | H16: 25000 | I16: Win | J16: =IF(I16="Loss",0,IF(OR(H16="",G16=""),"",IF(G16>0,H16*(1+G16/100),H16*(1+100/ABS(G16))))) -> 187500 | K16: =IF(H16="","",IF(I16="Loss",-H16,IF(J16="","",J16-H16))) -> 162500 | L16: BetMassachusetts tracker
A17: 2024-09-19 | B17: NFL | C17: New England Patriots +6 | D17: New York Jets | E17: 3-leg parlay: Pats +6, Rodgers U214.5 pass yds, Hunter Henry TD | F17: DraftKings | G17: 1500 | I17: Loss | J17: =IF(I17="Loss",0,IF(OR(H17="",G17=""),"",IF(G17>0,H17*(1+G17/100),H17*(1+100/ABS(G17))))) -> 0 | K17: =IF(H17="","",IF(I17="Loss",-H17,IF(J17="","",J17-H17))) | L17: BetMassachusetts tracker
A18: 2024-10-22 | B18: NBA | C18: Boston Celtics | D18: New York Knicks | E18: 6-leg SGP: Celtics -5.5, O114.5 team pts, Brown/White 3s, Tatum 25+, Brown 24+ | F18: DraftKings | G18: 1000 | I18: Loss | J18: =IF(I18="Loss",0,IF(OR(H18="",G18=""),"",IF(G18>0,H18*(1+G18/100),H18*(1+100/ABS(G18))))) -> 0 | K18: =IF(H18="","",IF(I18="Loss",-H18,IF(J18="","",J18-H18))) | L18: BetMassachusetts tracker
A19: 2024-11-10 | B19: NFL | C19: Ekeler / T. Hill / Dobbins TD | D19: Multiple | E19: 3-leg anytime TD parlay | F19: DraftKings | G19: 677 | I19: Loss | J19: =IF(I19="Loss",0,IF(OR(H19="",G19=""),"",IF(G19>0,H19*(1+G19/100),H19*(1+100/ABS(G19))))) -> 0 | K19: =IF(H19="","",IF(I19="Loss",-H19,IF(J19="","",J19-H19))) | L19: BetMassachusetts tracker
A20: 2024-11-15 | B20: Boxing | C20: Jake Paul | D20: Mike Tyson | E20: Moneyline | F20: DraftKings | G20: -200 | I20: Win | J20: =IF(I20="Loss",0,IF(OR(H20="",G20=""),"",IF(G20>0,H20*(1+G20/100),H20*(1+100/ABS(G20))))) | K20: =IF(H20="","",IF(I20="Loss",-H20,IF(J20="","",J20-H20))) | L20: BetMassachusetts tracker
A21: 2024-12-01 | B21: NFL | C21: Mixon / Hurts / Chase TD | D21: Multiple | E21: 3-leg anytime TD parlay | F21: DraftKings | G21: 412 | I21: Win | J21: =IF(I21="Loss",0,IF(OR(H21="",G21=""),"",IF(G21>0,H21*(1+G21/100),H21*(1+100/ABS(G21))))) | K21: =IF(H21="","",IF(I21="Loss",-H21,IF(J21="","",J21-H21))) | L21: BetMassachusetts tracker
A22: 2024-12-15 | B22: NFL | C22: Achane / B. Robinson / Chase TD | D22: Multiple | E22: 3-leg anytime TD parlay | F22: DraftKings | G22: 411 | I22: Loss | J22: =IF(I22="Loss",0,IF(OR(H22="",G22=""),"",IF(G22>0,H22*(1+G22/100),H22*(1+100/ABS(G22))))) -> 0 | K22: =IF(H22="","",IF(I22="Loss",-H22,IF(J22="","",J22-H22))) | L22: BetMassachusetts tracker
A23: 2024-12-29 | B23: NFL | C23: Pickett TD / J. Taylor 2 TD / B. Robinson TD | D23: Multiple | E23: 3-leg TD parlay (to win $362,900) | F23: DraftKings | G23: 3529 | H23: 10000 | I23: Loss | J23: =IF(I23="Loss",0,IF(OR(H23="",G23=""),"",IF(G23>0,H23*(1+G23/100),H23*(1+100/ABS(G23))))) -> 0 | K23: =IF(H23="","",IF(I23="Loss",-H23,IF(J23="","",J23-H23))) -> -10000 | L23: The Spun
A24: 2025-01-12 | B24: NFL | C24: Tampa Bay Buccaneers props + Daniels | D24: Washington Commanders | E24: 4-leg parlay: Evans TD, Irving TD, Irving 70+ rush, Daniels 40+ rush | F24: DraftKings | G24: 450 | H24: 11000 | I24: Loss | J24: =IF(I24="Loss",0,IF(OR(H24="",G24=""),"",IF(G24>0,H24*(1+G24/100),H24*(1+100/ABS(G24))))) -> 0 | K24: =IF(H24="","",IF(I24="Loss",-H24,IF(J24="","",J24-H24))) -> -11000 | L24: BetMassachusetts tracker
A25: 2025-01-19 | B25: NFL | C25: Buffalo Bills | D25: Field | E25: Futures — Super Bowl LIX champion | F25: DraftKings | G25: 550 | H25: 1000000 | I25: Loss | J25: =IF(I25="Loss",0,IF(OR(H25="",G25=""),"",IF(G25>0,H25*(1+G25/100),H25*(1+100/ABS(G25))))) -> 0 | K25: =IF(H25="","",IF(I25="Loss",-H25,IF(J25="","",J25-H25))) -> -1000000 | L25: Las Vegas Review-Journal / SI
A26: 2025-03-20 | B26: NCAAB | C26: Houston -28.5 / Michigan -2.5 / Arkansas +4.5 | D26: SIU Edwardsville / UC San Diego / Kansas | E26: 3-leg spread parlay — Round of 64 | F26: DraftKings | G26: 575 | I26: Win | J26: =IF(I26="Loss",0,IF(OR(H26="",G26=""),"",IF(G26>0,H26*(1+G26/100),H26*(1+100/ABS(G26))))) | K26: =IF(H26="","",IF(I26="Loss",-H26,IF(J26="","",J26-H26))) | L26: BetMassachusetts tracker
A27: 2025-03-20 | B27: NCAAB | C27: Michigan St / UNC / Michigan / Maryland | D27: Field | E27: 4-leg parlay — each to reach Sweet 16 | F27: DraftKings | G27: 2285 | I27: Loss | J27: =IF(I27="Loss",0,IF(OR(H27="",G27=""),"",IF(G27>0,H27*(1+G27/100),H27*(1+100/ABS(G27))))) -> 0 | K27: =IF(H27="","",IF(I27="Loss",-H27,IF(J27="","",J27-H27))) | L27: BetMassachusetts tracker
A28: 2025-05-05 | B28: NBA | C28: Boston Celtics props | D28: New York Knicks | E28: 3-leg parlay: White 4+ 3s, White 20+ pts, Tatum 4+ 3s (Game 1) | F28: DraftKings | G28: 750 | I28: Loss | J28: =IF(I28="Loss",0,IF(OR(H28="",G28=""),"",IF(G28>0,H28*(1+G28/100),H28*(1+100/ABS(G28))))) -> 0 | K28: =IF(H28="","",IF(I28="Loss",-H28,IF(J28="","",J28-H28))) | L28: BetMassachusetts tracker
A29: 2025-05-17 | B29: WNBA | C29: Caitlin Clark (Indiana Fever) | D29: Chicago Sky | E29: Prop — triple-double | F29: DraftKings | G29: 1300 | H29: 25000 | I29: Win | J29: =IF(I29="Loss",0,IF(OR(H29="",G29=""),"",IF(G29>0,H29*(1+G29/100),H29*(1+100/ABS(G29))))) -> 350000 | K29: =IF(H29="","",IF(I29="Loss",-H29,IF(J29="","",J29-H29))) -> 325000 | L29: BetMassachusetts tracker
A30: 2025-05-22 | B30: WNBA | C30: Indiana Fever props | D30: Atlanta Dream | E30: 3-leg parlay: Mitchell 20+, Boston 15+, Clark 12+ ast | F30: DraftKings | G30: 700 | I30: Loss | J30: =IF(I30="Loss",0,IF(OR(H30="",G30=""),"",IF(G30>0,H30*(1+G30/100),H30*(1+100/ABS(G30))))) -> 0 | K30: =IF(H30="","",IF(I30="Loss",-H30,IF(J30="","",J30-H30))) | L30: BetMassachusetts tracker
A31: 2025-05-31 | B31: NHL | C31: Edmonton Oilers | D31: Florida Panthers | E31: Series prop — Oilers win Final in 6 | F31: DraftKings | G31: 550 | H31: 50000 | I31: Loss | J31: =IF(I31="Loss",0,IF(OR(H31="",G31=""),"",IF(G31>0,H31*(1+G31/100),H31*(1+100/ABS(G31))))) -> 0 | K31: =IF(H31="","",IF(I31="Loss",-H31,IF(J31="","",J31-H31))) -> -50000 | L31: BetMassachusetts tracker
A32: 2025-10-05 | B32: NFL | C32: New England Patriots | D32: Field | E32: Futures — Super Bowl LX champion | F32: DraftKings | G32: 3500 | H32: 50000 | I32: Loss | J32: =IF(I32="Loss",0,IF(OR(H32="",G32=""),"",IF(G32>0,H32*(1+G32/100),H32*(1+100/ABS(G32))))) -> 0 | K32: =IF(H32="","",IF(I32="Loss",-H32,IF(J32="","",J32-H32))) -> -50000 | L32: LV Review-Journal / Yahoo
A33: 2025-11-29 | B33: CFB | C33: Michigan | D33: Ohio State | E33: Side bet w/ Urban Meyer — $1,000 to winner's NIL fund | F33: Personal (TV) | G33: 100 | H33: 1000 | I33: Loss | J33: =IF(I33="Loss",0,IF(OR(H33="",G33=""),"",IF(G33>0,H33*(1+G33/100),H33*(1+100/ABS(G33))))) -> 0 | K33: =IF(H33="","",IF(I33="Loss",-H33,IF(J33="","",J33-H33))) -> -1000 | L33: Yahoo Sports / NY Post
A34: 2026-05-03 | B34: NHL | C34: Vegas Golden Knights | D34: Field | E34: Futures — Stanley Cup champion | F34: DraftKings | G34: 650 | H34: 100000 | I34: Loss | J34: =IF(I34="Loss",0,IF(OR(H34="",G34=""),"",IF(G34>0,H34*(1+G34/100),H34*(1+100/ABS(G34))))) -> 0 | K34: =IF(H34="","",IF(I34="Loss",-H34,IF(J34="","",J34-H34))) -> -100000 | L34: LV Review-Journal / Covers
A36: Notes & assumptions:
A37: • Row 8 (Chiefs SB LVIII): odds not publicly reported; multiple outlets report the $500K bet roughly doubled, so payout is hardcoded at $1,000,000 (blue text).
A38: • Pick = the team/player/side Portnoy backed; Opponent = who they played ("Field" for futures/tournament winners, "Multiple" for cross-game parlays).
A39: • Nov 2023 row is an aggregate figure reported by OnlineBookiesOffers, not a single ticket.
A40: • Parlay rows with blank wagers were shown publicly on X but the stake was not reported; they are counted in the win/loss record but not in dollar totals.
A41: • Dec 29, 2024 parlay odds are back-calculated from the reported $10,000 stake / $362,900 potential payout.
A42: • Payout formula: for positive odds, Wager × (1 + Odds/100); for negative odds, Wager × (1 + 100/|Odds|). Losses = $0 payout.
...

Sheet Summary
A1: Summary — Publicly Reported Bets
A3: Total bets tracked | B3: =COUNTA(Bets!I5:I34) -> 30
A4: Wins | B4: =COUNTIF(Bets!I5:I34,"Win") -> 9
A5: Losses | B5: =COUNTIF(Bets!I5:I34,"Loss") -> 21
A6: Win rate | B6: =IF(B3=0,0,B4/B3) -> 0.3
A7: Bets with reported stake | B7: =COUNT(Bets!H5:H34) -> 20
A8: Total wagered (reported stakes) | B8: =SUM(Bets!H5:H34) -> 5052000
A9: Total payouts received | B9: =SUM(Bets!J5:J34) -> 7794957.6
A10: Net profit / loss | B10: =SUM(Bets!K5:K34) -> 2742957.6
A11: ROI on reported stakes | B11: =IF(B8=0,0,B10/B8) -> 0.5429449
A12: Biggest single win (net) | B12: =MAX(Bets!K5:K34) -> 2160000
A13: Biggest single loss (net) | B13: =MIN(Bets!K5:K34) -> -1000000
A14: Largest wager | B14: =MAX(Bets!H5:H34) -> 1000000
A17: By Sport
A18: Sport | B18: Bets | C18: Wins | D18: Losses | E18: Wagered ($) | F18: Net ($)
A19: Boxing | B19: =COUNTIF(Bets!$B$5:$B$34,A19) -> 1 | C19: =COUNTIFS(Bets!$B$5:$B$34,A19,Bets!$I$5:$I$34,"Win") -> 1 | D19: =COUNTIFS(Bets!$B$5:$B$34,A19,Bets!$I$5:$I$34,"Loss") -> 0 | E19: =SUMIF(Bets!$B$5:$B$34,A19,Bets!$H$5:$H$34) -> 0 | F19: =SUMIF(Bets!$B$5:$B$34,A19,Bets!$K$5:$K$34) -> 0
A20: CFB | B20: =COUNTIF(Bets!$B$5:$B$34,A20) -> 3 | C20: =COUNTIFS(Bets!$B$5:$B$34,A20,Bets!$I$5:$I$34,"Win") -> 1 | D20: =COUNTIFS(Bets!$B$5:$B$34,A20,Bets!$I$5:$I$34,"Loss") -> 2 | E20: =SUMIF(Bets!$B$5:$B$34,A20,Bets!$H$5:$H$34) -> 1501000 | F20: =SUMIF(Bets!$B$5:$B$34,A20,Bets!$K$5:$K$34) -> 346457.63
A21: Golf | B21: =COUNTIF(Bets!$B$5:$B$34,A21) -> 1 | C21: =COUNTIFS(Bets!$B$5:$B$34,A21,Bets!$I$5:$I$34,"Win") -> 1 | D21: =COUNTIFS(Bets!$B$5:$B$34,A21,Bets!$I$5:$I$34,"Loss") -> 0 | E21: =SUMIF(Bets!$B$5:$B$34,A21,Bets!$H$5:$H$34) -> 300000 | F21: =SUMIF(Bets!$B$5:$B$34,A21,Bets!$K$5:$K$34) -> 1350000
A22: MLB | B22: =COUNTIF(Bets!$B$5:$B$34,A22) -> 1 | C22: =COUNTIFS(Bets!$B$5:$B$34,A22,Bets!$I$5:$I$34,"Win") -> 0 | D22: =COUNTIFS(Bets!$B$5:$B$34,A22,Bets!$I$5:$I$34,"Loss") -> 1 | E22: =SUMIF(Bets!$B$5:$B$34,A22,Bets!$H$5:$H$34) -> 200000 | F22: =SUMIF(Bets!$B$5:$B$34,A22,Bets!$K$5:$K$34) -> -200000
A23: NBA | B23: =COUNTIF(Bets!$B$5:$B$34,A23) -> 2 | C23: =COUNTIFS(Bets!$B$5:$B$34,A23,Bets!$I$5:$I$34,"Win") -> 0 | D23: =COUNTIFS(Bets!$B$5:$B$34,A23,Bets!$I$5:$I$34,"Loss") -> 2 | E23: =SUMIF(Bets!$B$5:$B$34,A23,Bets!$H$5:$H$34) -> 0 | F23: =SUMIF(Bets!$B$5:$B$34,A23,Bets!$K$5:$K$34) -> 0
A24: NCAAB | B24: =COUNTIF(Bets!$B$5:$B$34,A24) -> 3 | C24: =COUNTIFS(Bets!$B$5:$B$34,A24,Bets!$I$5:$I$34,"Win") -> 2 | D24: =COUNTIFS(Bets!$B$5:$B$34,A24,Bets!$I$5:$I$34,"Loss") -> 1 | E24: =SUMIF(Bets!$B$5:$B$34,A24,Bets!$H$5:$H$34) -> 600000 | F24: =SUMIF(Bets!$B$5:$B$34,A24,Bets!$K$5:$K$34) -> 2160000
A25: NFL | B25: =COUNTIF(Bets!$B$5:$B$34,A25) -> 12 | C25: =COUNTIFS(Bets!$B$5:$B$34,A25,Bets!$I$5:$I$34,"Win") -> 2 | D25: =COUNTIFS(Bets!$B$5:$B$34,A25,Bets!$I$5:$I$34,"Loss") -> 10 | E25: =SUMIF(Bets!$B$5:$B$34,A25,Bets!$H$5:$H$34) -> 2001000 | F25: =SUMIF(Bets!$B$5:$B$34,A25,Bets!$K$5:$K$34) -> -1001000
A26: NHL | B26: =COUNTIF(Bets!$B$5:$B$34,A26) -> 3 | C26: =COUNTIFS(Bets!$B$5:$B$34,A26,Bets!$I$5:$I$34,"Win") -> 0 | D26: =COUNTIFS(Bets!$B$5:$B$34,A26,Bets!$I$5:$I$34,"Loss") -> 3 | E26: =SUMIF(Bets!$B$5:$B$34,A26,Bets!$H$5:$H$34) -> 300000 | F26: =SUMIF(Bets!$B$5:$B$34,A26,Bets!$K$5:$K$34) -> -300000
A27: WNBA | B27: =COUNTIF(Bets!$B$5:$B$34,A27) -> 3 | C27: =COUNTIFS(Bets!$B$5:$B$34,A27,Bets!$I$5:$I$34,"Win") -> 1 | D27: =COUNTIFS(Bets!$B$5:$B$34,A27,Bets!$I$5:$I$34,"Loss") -> 2 | E27: =SUMIF(Bets!$B$5:$B$34,A27,Bets!$H$5:$H$34) -> 125000 | F27: =SUMIF(Bets!$B$5:$B$34,A27,Bets!$K$5:$K$34) -> 225000
A28: WNBA/CFB | B28: =COUNTIF(Bets!$B$5:$B$34,A28) -> 1 | C28: =COUNTIFS(Bets!$B$5:$B$34,A28,Bets!$I$5:$I$34,"Win") -> 1 | D28: =COUNTIFS(Bets!$B$5:$B$34,A28,Bets!$I$5:$I$34,"Loss") -> 0 | E28: =SUMIF(Bets!$B$5:$B$34,A28,Bets!$H$5:$H$34) -> 25000 | F28: =SUMIF(Bets!$B$5:$B$34,A28,Bets!$K$5:$K$34) -> 162500
A29: Total | B29: =SUM(B19:B28) -> 30 | C29: =SUM(C19:C28) -> 9 | D29: =SUM(D19:D28) -> 21 | E29: =SUM(E19:E28) -> 5052000 | F29: =SUM(F19:F28) -> 2742957.6
A31: Dollar totals only include bets with a publicly reported stake. Win/loss counts include every tracked bet.
